INFO 2024-01-17 20:07:15,716 autoreload Watching for file changes with StatReloader
INFO 2024-01-17 20:14:04,825 autoreload Watching for file changes with StatReloader
INFO 2024-01-18 04:46:34,201 autoreload Watching for file changes with StatReloader
INFO 2024-01-18 04:50:49,281 autoreload Watching for file changes with StatReloader
INFO 2024-01-18 04:58:32,601 autoreload Watching for file changes with StatReloader
INFO 2024-01-18 05:01:24,722 basehttp "GET /swagger/ HTTP/1.1" 200 1580
INFO 2024-01-18 05:01:24,783 basehttp "GET /static/drf-yasg/style.css HTTP/1.1" 304 0
INFO 2024-01-18 05:01:24,784 basehttp "GET /static/drf-yasg/swagger-ui-dist/swagger-ui.css HTTP/1.1" 304 0
INFO 2024-01-18 05:01:24,785 basehttp "GET /static/drf-yasg/swagger-ui-dist/swagger-ui-standalone-preset.js HTTP/1.1" 304 0
INFO 2024-01-18 05:01:24,785 basehttp "GET /static/drf-yasg/swagger-ui-dist/swagger-ui-bundle.js HTTP/1.1" 304 0
INFO 2024-01-18 05:01:24,786 basehttp "GET /static/drf-yasg/insQ.min.js HTTP/1.1" 304 0
INFO 2024-01-18 05:01:24,787 basehttp "GET /static/drf-yasg/swagger-ui-init.js HTTP/1.1" 304 0
INFO 2024-01-18 05:01:24,787 basehttp "GET /static/drf-yasg/immutable.min.js HTTP/1.1" 304 0
INFO 2024-01-18 05:01:24,966 basehttp "GET /static/drf-yasg/swagger-ui-dist/favicon-32x32.png HTTP/1.1" 304 0
INFO 2024-01-18 05:01:24,979 basehttp "GET /swagger/?format=openapi HTTP/1.1" 200 4209
INFO 2024-01-18 05:01:30,808 basehttp "GET /api/v1/stories/ HTTP/1.1" 200 1931
INFO 2024-01-18 05:11:02,187 basehttp "GET /api/v1/stories/branches/3/ HTTP/1.1" 200 413
INFO 2024-01-18 05:38:22,700 basehttp "GET /api/v1/stories/ HTTP/1.1" 200 1931
INFO 2024-01-18 05:38:23,181 basehttp "GET /api/v1/stories/ HTTP/1.1" 200 1931
INFO 2024-01-18 05:38:23,834 basehttp "GET /api/v1/stories/ HTTP/1.1" 200 1931
INFO 2024-01-18 05:38:24,356 basehttp "GET /api/v1/stories/ HTTP/1.1" 200 1931
INFO 2024-01-18 05:38:24,873 basehttp "GET /api/v1/stories/ HTTP/1.1" 200 1931
INFO 2024-01-18 05:52:17,190 autoreload Watching for file changes with StatReloader
INFO 2024-01-18 05:58:45,797 autoreload Watching for file changes with StatReloader
INFO 2024-01-18 05:59:13,893 basehttp "GET /api/v1/stories/ HTTP/1.1" 200 1931
ERROR 2024-01-18 05:59:39,024 log Internal Server Error: /api/v1/stories/
Traceback (most recent call last):
  File "/usr/local/lib/python3.9/site-packages/django/core/handlers/exception.py", line 47, in inner
    response = get_response(request)
  File "/usr/local/lib/python3.9/site-packages/django/core/handlers/base.py", line 181, in _get_response
    response = wrapped_callback(request, *callback_args, **callback_kwargs)
  File "/usr/local/lib/python3.9/site-packages/django/views/decorators/csrf.py", line 54, in wrapped_view
    return view_func(*args, **kwargs)
  File "/usr/local/lib/python3.9/site-packages/django/views/generic/base.py", line 70, in view
    return self.dispatch(request, *args, **kwargs)
  File "/usr/local/lib/python3.9/site-packages/rest_framework/views.py", line 509, in dispatch
    response = self.handle_exception(exc)
  File "/usr/local/lib/python3.9/site-packages/rest_framework/views.py", line 469, in handle_exception
    self.raise_uncaught_exception(exc)
  File "/usr/local/lib/python3.9/site-packages/rest_framework/views.py", line 480, in raise_uncaught_exception
    raise exc
  File "/usr/local/lib/python3.9/site-packages/rest_framework/views.py", line 506, in dispatch
    response = handler(request, *args, **kwargs)
  File "/usr/local/lib/python3.9/site-packages/rest_framework/decorators.py", line 50, in handler
    return func(*args, **kwargs)
  File "/story/views.py", line 80, in story_list_create
    image_url = s3_upload(image_url)  # s3 업로드 후 버킷 url
  File "/story/views.py", line 167, in s3_upload
    image = requests.get(image_url)
  File "/usr/local/lib/python3.9/site-packages/requests/api.py", line 73, in get
    return request("get", url, params=params, **kwargs)
  File "/usr/local/lib/python3.9/site-packages/requests/api.py", line 59, in request
    return session.request(method=method, url=url, **kwargs)
  File "/usr/local/lib/python3.9/site-packages/requests/sessions.py", line 575, in request
    prep = self.prepare_request(req)
  File "/usr/local/lib/python3.9/site-packages/requests/sessions.py", line 486, in prepare_request
    p.prepare(
  File "/usr/local/lib/python3.9/site-packages/requests/models.py", line 368, in prepare
    self.prepare_url(url, params)
  File "/usr/local/lib/python3.9/site-packages/requests/models.py", line 439, in prepare_url
    raise MissingSchema(
requests.exceptions.MissingSchema: Invalid URL 'www.dlkfaj.cald': No scheme supplied. Perhaps you meant https://www.dlkfaj.cald?
ERROR 2024-01-18 05:59:39,029 basehttp "POST /api/v1/stories/ HTTP/1.1" 500 17504
ERROR 2024-01-18 05:59:54,114 log Internal Server Error: /api/v1/stories/
Traceback (most recent call last):
  File "/usr/local/lib/python3.9/site-packages/urllib3/connection.py", line 174, in _new_conn
    conn = connection.create_connection(
  File "/usr/local/lib/python3.9/site-packages/urllib3/util/connection.py", line 72, in create_connection
    for res in socket.getaddrinfo(host, port, family, socket.SOCK_STREAM):
  File "/usr/local/lib/python3.9/socket.py", line 954, in getaddrinfo
    for res in _socket.getaddrinfo(host, port, family, type, proto, flags):
socket.gaierror: [Errno -2] Name or service not known

During handling of the above exception, another exception occurred:

Traceback (most recent call last):
  File "/usr/local/lib/python3.9/site-packages/urllib3/connectionpool.py", line 715, in urlopen
    httplib_response = self._make_request(
  File "/usr/local/lib/python3.9/site-packages/urllib3/connectionpool.py", line 404, in _make_request
    self._validate_conn(conn)
  File "/usr/local/lib/python3.9/site-packages/urllib3/connectionpool.py", line 1058, in _validate_conn
    conn.connect()
  File "/usr/local/lib/python3.9/site-packages/urllib3/connection.py", line 363, in connect
    self.sock = conn = self._new_conn()
  File "/usr/local/lib/python3.9/site-packages/urllib3/connection.py", line 186, in _new_conn
    raise NewConnectionError(
urllib3.exceptions.NewConnectionError: <urllib3.connection.HTTPSConnection object at 0xffff83471d30>: Failed to establish a new connection: [Errno -2] Name or service not known

During handling of the above exception, another exception occurred:

Traceback (most recent call last):
  File "/usr/local/lib/python3.9/site-packages/requests/adapters.py", line 486, in send
    resp = conn.urlopen(
  File "/usr/local/lib/python3.9/site-packages/urllib3/connectionpool.py", line 799, in urlopen
    retries = retries.increment(
  File "/usr/local/lib/python3.9/site-packages/urllib3/util/retry.py", line 592, in increment
    raise MaxRetryError(_pool, url, error or ResponseError(cause))
urllib3.exceptions.MaxRetryError: HTTPSConnectionPool(host='www.dlkfaj.cald', port=443): Max retries exceeded with url: / (Caused by NewConnectionError('<urllib3.connection.HTTPSConnection object at 0xffff83471d30>: Failed to establish a new connection: [Errno -2] Name or service not known'))

During handling of the above exception, another exception occurred:

Traceback (most recent call last):
  File "/usr/local/lib/python3.9/site-packages/django/core/handlers/exception.py", line 47, in inner
    response = get_response(request)
  File "/usr/local/lib/python3.9/site-packages/django/core/handlers/base.py", line 181, in _get_response
    response = wrapped_callback(request, *callback_args, **callback_kwargs)
  File "/usr/local/lib/python3.9/site-packages/django/views/decorators/csrf.py", line 54, in wrapped_view
    return view_func(*args, **kwargs)
  File "/usr/local/lib/python3.9/site-packages/django/views/generic/base.py", line 70, in view
    return self.dispatch(request, *args, **kwargs)
  File "/usr/local/lib/python3.9/site-packages/rest_framework/views.py", line 509, in dispatch
    response = self.handle_exception(exc)
  File "/usr/local/lib/python3.9/site-packages/rest_framework/views.py", line 469, in handle_exception
    self.raise_uncaught_exception(exc)
  File "/usr/local/lib/python3.9/site-packages/rest_framework/views.py", line 480, in raise_uncaught_exception
    raise exc
  File "/usr/local/lib/python3.9/site-packages/rest_framework/views.py", line 506, in dispatch
    response = handler(request, *args, **kwargs)
  File "/usr/local/lib/python3.9/site-packages/rest_framework/decorators.py", line 50, in handler
    return func(*args, **kwargs)
  File "/story/views.py", line 80, in story_list_create
    image_url = s3_upload(image_url)  # s3 업로드 후 버킷 url
  File "/story/views.py", line 167, in s3_upload
    image = requests.get(image_url)
  File "/usr/local/lib/python3.9/site-packages/requests/api.py", line 73, in get
    return request("get", url, params=params, **kwargs)
  File "/usr/local/lib/python3.9/site-packages/requests/api.py", line 59, in request
    return session.request(method=method, url=url, **kwargs)
  File "/usr/local/lib/python3.9/site-packages/requests/sessions.py", line 589, in request
    resp = self.send(prep, **send_kwargs)
  File "/usr/local/lib/python3.9/site-packages/requests/sessions.py", line 703, in send
    r = adapter.send(request, **kwargs)
  File "/usr/local/lib/python3.9/site-packages/requests/adapters.py", line 519, in send
    raise ConnectionError(e, request=request)
requests.exceptions.ConnectionError: HTTPSConnectionPool(host='www.dlkfaj.cald', port=443): Max retries exceeded with url: / (Caused by NewConnectionError('<urllib3.connection.HTTPSConnection object at 0xffff83471d30>: Failed to establish a new connection: [Errno -2] Name or service not known'))
ERROR 2024-01-18 05:59:54,116 basehttp "POST /api/v1/stories/ HTTP/1.1" 500 19916
INFO 2024-01-18 06:00:45,799 basehttp "POST /api/v1/stories/ HTTP/1.1" 201 247
